Workbook

Sheet 01 README
A1: Hiver Technology - SEO Master Workbook
A2: Prepared 2026-08-14. Benchmarked against a supplied 253-URL competitor audit (nexly.com.au) and a live inspection of hiver.com.np.
A3: Item | B3: Detail
A4: What this workbook is | B4: An SEO, architecture and content plan for Hiver Technology (hiver.com.np), benchmarked against a real competitor site audit (nexly.com.au, 253 URLs) supplied by the client, plus a live inspection of hiver.com.np.
A5: Verification date | B5: 2026-08-14. Every SERP, competitor and site observation in this workbook was made on or before this date. Re-verify before acting on anything time-sensitive.
A6: Provenance rule | B6: Every data point carries a Source label. No search volume, keyword difficulty, CPC or backlink figure has been invented. Cells reading DATA REQUIRED must be filled from a paid tool or from Hiver before the plan is final.
A7: Source labels used | B7: [VERIFIED-SITE] observed directly on the live site | [VERIFIED-FILE] taken from the supplied Nexly audit file | [COMPETITOR-DERIVED] inferred from a competitor's actual page/title/URL choices | [STRATEGIC-JUDGEMENT] the analyst's reasoning, no metric behind it | [DATA REQUIRED] unavailable, must be sourced
A8: Cell colour convention | B8: Blue text = an input you can change (scoring weights). Yellow fill = a gap that must be filled before launch. Black text = formula or fixed research output.
A9: Which cells to edit | B9: Scoring Model!B5:B8 (the four weights, must total 100%) and the tier multipliers below them. Master Keywords columns F-H (Volume / KD / CPC) once you have Ahrefs or Semrush access. Any cell marked DATA REQUIRED. Everything else is derived.
A10: How the priority score works | B10: Master Keywords column P weights four 1-5 judgement scores and rescales to 0-100. Column Q then multiplies that by the winnability multiplier for the keyword's tier, so a head term Hiver cannot win drops to the bottom instead of topping the list on commercial intent. Sort by column Q. Change any weight or multiplier and every score recalculates. The score prioritises work; it does not predict rankings.
A11: Reading order | B11: 1. Exec Summary 2. Hiver Baseline 3. Competitor Benchmark 4. Gap Matrix 5. Master Keywords 6. URL Map 7. Page SEO 8. Content Briefs 9. everything else as needed.
A12: What this workbook does not do | B12: It does not promise rankings, does not claim tool-verified volumes, and does not plan pages for services Hiver has not confirmed it delivers. Capability-gated pages are flagged in the URL Map.
A15: Legend
A16: Blue text | B16: An input cell you can change (see Scoring Model)
A17: Yellow fill | B17: A gap that must be filled before launch - marked DATA REQUIRED
A18: Black text | B18: Formula output or fixed research finding

Sheet 02 Exec Summary
A1: Executive summary - ten findings that shape the plan
A2: Every finding is sourced. Findings 2, 3 and 7 must be resolved before any page is built.
A3: Finding | B3: Detail | C3: Source
A4: 1. The honest starting position | B4: hiver.com.np is a partially built WordPress/Elementor template, not a functioning agency site. It carries an 'Under Construction' banner, unedited demo testimonials, placeholder client-logo alt text, and nav/footer links that point to '#'. There are no service pages. Treat this as a build, not an optimisation. | C4: [VERIFIED-SITE]
A5: 2. The domain is a structural handicap | B5: .com.np is a Nepal country-code namespace. Google treats ccTLDs as a geographic signal and Search Console's international-targeting override has historically applied only to generic TLDs. Competing for US/AU/UK commercial terms from this domain adds a headwind on top of the authority gap. A gTLD decision must be made before any URL is built. | C5: [STRATEGIC-JUDGEMENT]
A6: 3. The brand name is taken | B6: 'Hiver' is an established customer-service SaaS company (hiverhq.com) with a large review and content footprint. The branded SERP is not winnable. All navigational search must be built around 'Hiver Technology'. Trademark exposure in the US/AU/UK is a question for a qualified attorney, not for this workbook. | C6: [VERIFIED-SITE]
A7: 4. The competitor proves the market is winnable | B7: Nexly runs 253 URLs: 69 templated Shopify service pages, 119 blog posts, 15 integration pages, 11 migration pages, 7 case studies. Its co-founder and SEO lead links to a Nepal LinkedIn profile while two directors link to Australian profiles. A distributed Nepal-plus-onshore team is already competing successfully for Australian Shopify work. This is the closest available model of what works. | C7: [VERIFIED-FILE]
A8: 5. The competitor's weaknesses are Hiver's openings | B8: Across all 253 Nexly URLs the audit detected no structured data at all, every page has images missing alt text, 122 titles exceed 60 characters, 31 pages have no meta description, and 27 pages are under 300 words (team pages, case studies, blog categories). Case studies average roughly 400 words despite carrying strong results. | C8: [VERIFIED-FILE]
A9: 6. Where Hiver can realistically rank first | B9: Not on head terms. The winnable ground is narrow and specific: integration and migration pairings, platform-plus-problem queries, cost and comparison questions, 'hire a dedicated developer' intent where offshore delivery is an advantage, and the vertical software categories tied to Hiver's own products. See the Winnability tier column on Master Keywords. | C9: [STRATEGIC-JUDGEMENT]
A10: 7. The Shopify plan is gated on capability | B10: The brief treats Shopify as a flagship service, but no Shopify page exists on hiver.com.np and Hiver's Shopify track record is unconfirmed. Every Shopify page in this workbook is marked capability-gated. Do not publish them until Hiver confirms delivered stores, Partner status and at least one referenceable project. | C10: [VERIFIED-SITE]
A11: 8. The overlooked asset | B11: Hiver's footer lists vertical software products (school, dental, clinic, HR management) that the original brief never mentioned. Product-category search is typically less contested than agency search and monetises directly. This deserves its own section and its own decision. | C11: [VERIFIED-SITE]
A12: 9. Distribution matters as much as ranking | B12: For agency buying in the US/AU/UK, Clutch, G2, DesignRush, GoodFirms, Upwork and the Shopify Partner directory frequently occupy the commercial SERP and are where shortlists form. Profile completion is a launch-phase task, not a later one. | C12: [STRATEGIC-JUDGEMENT]
A13: 10. What has to happen first | B13: Phase 0 is unblocking, not SEO: remove the construction banner, delete the demo testimonials and placeholder logos, fix every '#' link, resolve the domain and brand decisions, install analytics and Search Console, replace the 'superadmin' author identity. Nothing else in this workbook is worth doing before that. | C13: [VERIFIED-SITE]

Sheet 03 Hiver Baseline
A1: Hiver baseline audit - live site, verified 2026-08-14
A2: Observed directly on hiver.com.np. Re-verify before acting; the site may change.
A3: ID | B3: Area | C3: Finding | D3: Evidence | E3: Business impact | F3: Severity | G3: Owner | H3: Action
A4: B01 | B4: Trust | C4: Site displays an 'Website Still Under Construction' banner | D4: Homepage, observed 2026-08-14 | E4: Any US/AU/UK buyer who lands here disqualifies Hiver in seconds | F4: Blocker | G4: Marketing | H4: Remove banner or take the site offline until launch-ready
A5: B02 | B5: Legal / Trust | C5: Six testimonials are unedited theme demo content ('Sarah', 'John Farrel', 'John Doe Iswanto', 'Jackma Kalin', 'Darsono', 'Ismail'); copy refers to a copywriting service | D5: Homepage testimonials block | E5: Fabricated endorsements. Consumer-protection exposure with the FTC (US), ACCC (AU) and CMA/ASA (UK); severe E-E-A-T damage | F5: Blocker | G5: Founder | H5: Delete entirely. Do not rewrite. Replace only with permissioned real testimonials
A6: B03 | B6: Trust | C6: Client logo alt text reads 'Brand Name : Brand Short Description Type Here.'; one logo in the client strip is Hiver's own logo | D6: Homepage client strip | E6: Placeholder content shipped live; implies fabricated client roster | F6: Blocker | G6: Marketing | H6: Remove until real permissioned logos exist
A7: B04 | B7: Crawl / IA | C7: Almost all main nav and footer links resolve to '#' | D7: Header and footer markup | E7: No crawlable internal link graph. Existing child pages are effectively orphaned | F7: Blocker | G7: Dev | H7: Build the real URL structure and wire every nav item to it
A8: B05 | B8: Architecture | C8: No service pages exist. Live services are only listed as homepage cards: Web Applications, Mobile Apps, Responsive Websites, CRM Web Applications, UI/UX Design, Digital Marketing | D8: Homepage services block | E8: Zero commercial landing pages; nothing can rank or convert | F8: Critical | G8: Content | H8: Build the P0 service pages in the URL Map tab
A9: B06 | B9: Scope mismatch | C9: The brief's service list (Shopify, SEO services, email marketing, automations) does not exist on the live site | D9: Site vs brief comparison | E9: Plan must be a build, and Shopify/SEO pages must be capability-gated | F9: Critical | G9: Founder | H9: Confirm which services are genuinely delivered today (see Data Required tab)
A10: B07 | B10: Opportunity | C10: Footer lists products: School Management, Dental Management, Clinic Management, HR Software, Employee Management | D10: Footer products column | E10: Potentially the strongest and least contested search opportunity; absent from the brief | F10: Critical opportunity | G10: Founder | H10: Confirm product status, then build the /products/ section
A11: B08 | B11: URL structure | C11: Blog posts sit at root (e.g. /programmer-developer-and-engineer-explained/) while /insights/ also exists | D11: Homepage news block | E11: Inconsistent structure; a redirect map is required before restructuring | F11: High | G11: Dev | H11: Move posts under /insights/ with 301s; never leave both live
A12: B09 | B12: E-E-A-T | C12: Author metadata is 'superadmin' | D12: twitter:data1 meta value | E12: No human author entity; fails author-level E-E-A-T and looks unmaintained | F12: High | G12: Content | H12: Create real author profiles with credentials and byline them
A13: B10 | B13: Content quality | C13: Visible typos in live copy: 'Developemnt', 'Transfering', "help's", 'Insitagram' | D13: Homepage and footer | E13: Premium-market buyers read this as low care and low capability | F13: High | G13: Content | H13: Full copy proof before launch
A14: B11 | B14: On-page | C14: Homepage title is 'Hiver Technology | AI-Powered Software, Apps & Web Solutions' | D14: Title tag | E14: No commercial keyword, no market signal, no service specificity | F14: High | G14: SEO | H14: Rewrite per the Page SEO tab
... A21: B18 | B21: Images | C21: Hero and section imagery is generic stock (e.g. pexels files) | D21: Homepage image paths | E21: Reads as templated; no product or interface proof | F21: Medium | G21: Design | H21: Replace with real interface, product and process visuals

Sheet 04 Competitor Benchmark
A1: Competitor benchmark - nexly.com.au (253 URLs)
A2: All figures from the supplied audit file. This is the depth and structure bar Hiver is measured against.
A3: Metric | B3: Competitor | C3: Hiver today | D3: What it means for Hiver | E3: Source
A4: Total indexable URLs discovered | B4: 253 | C4: Approx. 6 reachable, most nav links dead | D4: Hiver needs a real site before it needs an SEO plan | E4: [VERIFIED-FILE] / [VERIFIED-SITE]
A5: Templated service pages | B5: 69 | C5: 0 | D5: The single biggest structural gap | E5: [VERIFIED-FILE]
A6: Median words, service page | B6: 1,281 (range 839-2,446) | C6: n/a | D6: This is the depth bar for a Hiver service page: roughly 1,200-1,600 words | E6: [VERIFIED-FILE]
A7: H2 sections per service page | B7: 11 (highly consistent) | C7: n/a | D7: Evidence of one reusable template applied at scale, not bespoke pages | E7: [VERIFIED-FILE]
A8: Blog posts | B8: 119 | C8: 2 (2024, Nepal-focused) | D8: Content programme is the competitor's main moat | E8: [VERIFIED-FILE]
A9: Median words, blog post | B9: 1,837 (range 519-2,471) | C9: n/a | D9: Depth bar for Hiver insight articles | E9: [VERIFIED-FILE]
A10: Integration pages | B10: 15 (Xero, MYOB, NetSuite, SAP, Cin7, HubSpot, Salesforce, Klaviyo, Dynamics 365, Akeneo, Shippit, Starshipit, Australia Post, 3PL/WMS) | C10: 0 | D10: Platform-plus-system pairings are the clearest winnable long-tail pattern in the whole dataset | E10: [VERIFIED-FILE]
A11: Median words, integration page | B11: 968 (8-9 H2s) | C11: n/a | D11: Shorter than service pages; a realistic first content target | E11: [VERIFIED-FILE]
A12: Migration pages | B12: 11 (Magento, Adobe Commerce, BigCommerce, WooCommerce, PrestaShop, OpenCart, SFCC, custom platform, theme, Shopify-to-Plus) | C12: 0 | D12: 'X to Y migration' is a repeatable, high-intent page pattern | E12: [VERIFIED-FILE]
A13: Case studies | B13: 7 (EzyDog AU/NZ/UK/EU/USA, Town & Country Covers) | C13: 0 | D13: One client family carries five of seven case studies | E13: [VERIFIED-FILE]
A14: Median words, case study | B14: 399 (range 344-747) | C14: n/a | D14: Thin. Hiver can beat this on depth with a single well-documented project | E14: [VERIFIED-FILE]
... A29: Case study proof style | B29: Named client, named markets, specific outcome claims, service tags, live store link | C29: None | D29: Hiver cannot match this until it has permissioned client data. This is the critical blocker | E29: [VERIFIED-FILE]

Sheet 05 Page Archetypes
A1: Page archetypes observed in the competitor set
A2: Extracted from real heading structures. Use as templates; do not copy wording.
A3: Page type | B3: Example URL | C3: Words | D3: H2 count | E3: Section sequence | F3: Why it works / how to beat it | G3: Source
A4: Service page | B4: /services/shopify-development/ | C4: 1,580 | D4: 12 | E4: H1 outcome statement | Problem question | Choose your path | Choose approach | What we build | What you get, stage by stage | How we run a build | Tested before it ships | What it costs | FAQs | Related services | Intent-matched CTA | Site-wide CTA | F4: Cost section on a service page is unusual and high-value. Problem-first H2 as a question. Two CTAs: one page-specific, one site-wide. | G4: [VERIFIED-FILE]
A5: Migration page | B5: /migrations/magento-to-shopify/ | C5: 1,066 | D5: 8 | E5: H1 'X to Y migration' | Why brands leave X | What moves across | What the migration covers | How it runs | FAQs | Related services | Assessment CTA | Site-wide CTA | F5: 'What moves across' is the buyer's real question and the reason this page type converts. Repeatable per source platform. | G5: [VERIFIED-FILE]
A6: Integration page | B6: /integrations/shopify-xero/ | C6: 985 | D6: 9 | E6: H1 'A + B integration' | The manual cost of not integrating | What syncs, which way | What a proper integration covers | How we build it | What it costs | FAQs | Related services | Scope CTA | Site-wide CTA | F6: Cheapest page type to produce (roughly 950 words) and the most obviously winnable pattern. 'What syncs, which way' is the differentiator. | G6: [VERIFIED-FILE]
A7: Case study | B7: /case-studies/ezydog-au/ | C7: 506 | D7: 3 (mostly H3 steps) | E7: H1 outcome sentence | Metric strip | Service tags | The challenge | What we did (numbered steps) | The outcome | More case studies | 'Could your store be next' CTA | F7: Short but effective because the metrics are specific. Hiver should use the same skeleton with more depth and verified numbers only. | G7: [VERIFIED-FILE]
A8: Homepage | B8: / | C8: 3,136 | D8: 13 | E8: Outcome H1 | Client logos | Value proposition | Primary service depth | Why the approach | Comparison table | What's included | Tech stack | Process | Proof | Named team with photos | FAQ | CTA | F8: Named team on the homepage is a deliberate trust device for a remote-delivery buyer. Hiver should copy the intent, not the layout. | G8: [VERIFIED-FILE]
A9: Enquiry page | B9: /project-enquiry/ | C9: 862 | D9: 5 | E9: Three steps: Project (multi-select services) | Business (URL, platform, revenue band, budget band, start date) | Contact, with conditional per-service qualifier blocks | F9: Qualification happens in the form, not in a sales call. This is the single most copyable asset in the competitor set. | G9: [VERIFIED-FILE]

Sheet 06 Gap Matrix
A1: Competitor gap matrix
A2: Opportunity ranks the size of the prize; Effort ranks what it costs Hiver to close.
A3: Topic / asset | B3: Hiver | C3: Competitor | D3: Gap type | E3: Opportunity | F3: Effort | G3: Priority | H3: Recommendation
A4: Commercial service pages | B4: None | C4: 69 templated pages | D4: Service | E4: High | F4: High | G4: P0 | H4: Build 8-10 genuinely differentiated service pages first. Do not attempt 69.
A5: Integration pages (platform + system) | B5: None | C5: 15 pages, ~968 words each | D5: Content / long-tail | E5: High | F5: Medium | G5: P1 | H5: Strongest winnable pattern in the dataset. Build only for systems Hiver has actually integrated.
A6: Migration pages (X to Y) | B6: None | C6: 11 pages | D6: Content / high intent | E6: High | F6: Medium | G6: P1 | H6: Start with WordPress/WooCommerce migrations where Hiver's capability is most credible.
A7: Structured data | B7: None | C7: None detected on 253 URLs | D7: Technical | E7: Medium | F7: Low | G7: P0 | H7: Immediate differentiator. Organization, WebSite, BreadcrumbList, Service, Article, Person, SoftwareApplication.
A8: Image alt text | B8: Placeholder text | C8: Missing on all 253 pages | D8: Technical / accessibility | E8: Medium | F8: Low | G8: P0 | H8: Trivial to win. Also required for the WCAG position below.
A9: Accessibility (WCAG 2.2 AA) | B9: Unknown | C9: Sells the service; fails basic alt text | D9: Trust / technical | E9: Medium | F9: Medium | G9: P1 | H9: Compliance on Hiver's own site makes the claim credible and matters for AU/UK procurement.
A10: Title tag discipline | B10: Weak | C10: 122 of 253 titles over 60 characters | D10: On-page / CTR | E10: Medium | F10: Low | G10: P0 | H10: Keep every title under 60 characters. See Page SEO tab.
A11: Case studies with verified metrics | B11: None | C11: 7, thin but specific | D11: Proof | E11: Critical | F11: High | G11: P0 (blocked) | H11: The hard blocker. One deeply documented, permissioned project beats seven thin ones.
A12: Named team with credentials | B12: Team page exists, thin | C12: 8 profiles, median 123 words | D12: Trust | E12: High | F12: Low | G12: P0 | H12: Beat this easily: real photos, real experience, real specialisms, linked LinkedIn profiles.
A13: Qualified enquiry form | B13: 'Get a Quote' link | C13: 3-step conditional qualifier | D13: Conversion | E13: High | F13: Medium | G13: P0 | H13: Adopt the pattern. See Conversion tab for the recommended field set.
A14: Intent-matched CTAs | B14: One generic CTA | C14: 7+ distinct CTA framings | D14: Conversion | E14: Medium | F14: Low | G14: P0 | H14: Match the CTA to page intent: audit, assessment, scope, discovery call.
... A23: Thin category archives | B23: None | C23: 16 thin indexable categories | D23: Technical | E23: n/a | F23: n/a | G23: Avoid | H23: Do not copy. Noindex thin archives or give them real introductory content.

Sheet 07 Scoring Model
A1: Scoring model - edit the weights, every keyword score recalculates
A2: Blue cells are inputs. The four weights must total 100%. Winnability is not a fifth weight - it is a multiplier applied after the weighted score, so an unwinnable keyword cannot be scored into the launch plan by high commercial intent alone.
A4: Factor | B4: Weight | C4: What it measures
A5: Commercial intent | B5: 0.35 | C5: How close the searcher is to paying someone
A6: Business value / capability fit | B6: 0.3 | C6: Deal size, and whether Hiver can genuinely deliver it today
A7: Search volume proxy | B7: 0.2 | C7: 1-5 judgement until real tool data replaces it
A8: Strategic relevance | B8: 0.15 | C8: Cluster and positioning value beyond the single keyword
A9: Total | B9: =SUM(B5:B8) -> 1 | C9: Must equal 100%
A12: Winnability tier table - the multiplier applied to the weighted score
A13: Tier | B13: Multiplier | C13: Meaning | D13: How to recognise it in the SERP
A14: A | B14: 1 | C14: Winnable in 0-6 months | D14: Top 10 contains thin, off-intent or non-agency results. Usually 4+ word specific phrases. Target these now.
A15: B | B15: 0.8 | C15: Winnable in 6-12 months with depth plus some links | D15: Top 10 is mostly mid-authority agencies with adequate but beatable pages.
A16: C | B16: 0.55 | C16: Winnable only with 12-24 months of authority investment | D16: Top 10 is high-authority or directory-dominated. Build the page for coverage, but do not bet the launch on the keyword.
A17: D | B17: 0.25 | C17: Not winnable as an organic bet | D17: Directory- or incumbent-locked. The page may still be needed for coverage; win the customer through paid, directories, partnerships or outbound instead.
A20: Method note
A21: Method: Weighted score = (commercial intent x W1 + business value x W2 + volume proxy x W3 + strategic relevance x W4) x 20, giving 0-100. Priority score = weighted score x the winnability multiplier for that keyword's tier. This is deliberate: a Tier D head term with perfect commercial intent lands near the bottom, which is the correct answer for a low-authority domain. The four 1-5 inputs on the Master Keywords tab are the analyst's judgement, labelled [STRATEGIC-JUDGEMENT] unless the source column says otherwise. They are not tool metrics. Replace the volume proxy with real data as soon as an Ahrefs or Semrush seat exists, then re-read the priority order. Rank band reads the keyword as an organic bet, not the page. A page can still be worth building for coverage while its head keyword is scored 'do not chase' - see the URL Map, where several such pages are P0.

Sheet 08 Master Keywords
A1: Master keyword universe
A2: No volume, difficulty or CPC figure has been invented. Columns F-H are yellow because they require a paid tool. Columns J-M are judgement scores. Column P is the weighted score; column Q multiplies it by the winnability tier, so unwinnable keywords cannot climb the list on commercial intent alone. Sort by column Q.
A3: Keyword | B3: Intent | C3: Country | D3: Target URL | E3: Page type | F3: Volume | G3: KD | H3: CPC | I3: Metric source | J3: Commercial intent (1-5) | K3: Business value (1-5) | L3: Volume proxy (1-5) | M3: Strategic relevance (1-5) | N3: Winnability tier | O3: Tier multiplier | P3: Weighted score | Q3: Priority score (0-100) | R3: Rank band as an organic bet | S3: Evidence source | T3: Note
A4: custom web application development | B4: Transactional | C4: US | D4: /services/web-application-development/ | E4: Service | F4: DATA REQUIRED | G4: DATA REQUIRED | H4: DATA REQUIRED | I4: [DATA REQUIRED - PAID TOOL] | J4: 5 | K4: 5 | L4: 4 | M4: 5 | N4: C | O4: =IFERROR(INDEX('07 Scoring Model'!$B$14:$B$17,MATCH(N4,'07 Scoring Model'!$A$14:$A$17,0)),0) -> 0.55 | P4: =ROUND((J4*'07 Scoring Model'!$B$5 + K4*'07 Scoring Model'!$B$6 + L4*'07 Scoring Model'!$B$7 + M4*'07 Scoring Model'!$B$8)*20,1) -> 96 | Q4: =ROUND(P4*O4,1) -> 52.8 | R4: =IF(Q4>=70,"1 - Target now",IF(Q4>=55,"2 - Target next",IF(Q4>=40,"3 - Support only",IF(Q4>=28,"4 - Defer","5 - Do not chase organically")))) -> 3 - Support only | S4: [COMPETITOR-DERIVED] | T4: Head term; agency-dominated. Support page, not a first win
A5: custom web application development company | B5: Transactional | C5: US | D5: /services/web-application-development/ | E5: Service | F5: DATA REQUIRED | G5: DATA REQUIRED | H5: DATA REQUIRED | I5: [DATA REQUIRED - PAID TOOL] | J5: 5 | K5: 5 | L5: 3 | M5: 5 | N5: C | O5: =IFERROR(INDEX('07 Scoring Model'!$B$14:$B$17,MATCH(N5,'07 Scoring Model'!$A$14:$A$17,0)),0) -> 0.55 | P5: =ROUND((J5*'07 Scoring Model'!$B$5 + K5*'07 Scoring Model'!$B$6 + L5*'07 Scoring Model'!$B$7 + M5*'07 Scoring Model'!$B$8)*20,1) -> 92 | Q5: =ROUND(P5*O5,1) -> 50.6 | R5: =IF(Q5>=70,"1 - Target now",IF(Q5>=55,"2 - Target next",IF(Q5>=40,"3 - Support only",IF(Q5>=28,"4 - Defer","5 - Do not chase organically")))) -> 3 - Support only | S5: [STRATEGIC-JUDGEMENT] | T5: Same intent as above; do not build a separate page
A6: web application development services | B6: Transactional | C6: UK | D6: /services/web-application-development/ | E6: Service | F6: DATA REQUIRED | G6: DATA REQUIRED | H6: DATA REQUIRED | I6: [DATA REQUIRED - PAID TOOL] | J6: 5 | K6: 5 | L6: 3 | M6: 4 | N6: C | O6: =IFERROR(INDEX('07 Scoring Model'!$B$14:$B$17,MATCH(N6,'07 Scoring Model'!$A$14:$A$17,0)),0) -> 0.55 | P6: =ROUND((J6*'07 Scoring Model'!$B$5 + K6*'07 Scoring Model'!$B$6 + L6*'07 Scoring Model'!$B$7 + M6*'07 Scoring Model'!$B$8)*20,1) -> 89 | Q6: =ROUND(P6*O6,1) -> 49 | R6: =IF(Q6>=70,"1 - Target now",IF(Q6>=55,"2 - Target next",IF(Q6>=40,"3 - Support only",IF(Q6>=28,"4 - Defer","5 - Do not chase organically")))) -> 3 - Support only | S6: [STRATEGIC-JUDGEMENT]
A7: custom crm development | B7: Transactional | C7: US | D7: /services/crm-development/ | E7: Service | F7: DATA REQUIRED | G7: DATA REQUIRED | H7: DATA REQUIRED | I7: [DATA REQUIRED - PAID TOOL] | J7: 5 | K7: 5 | L7: 3 | M7: 5 | N7: B | O7: =IFERROR(INDEX('07 Scoring Model'!$B$14:$B$17,MATCH(N7,'07 Scoring Model'!$A$14:$A$17,0)),0) -> 0.8 | P7: =ROUND((J7*'07 Scoring Model'!$B$5 + K7*'07 Scoring Model'!$B$6 + L7*'07 Scoring Model'!$B$7 + M7*'07 Scoring Model'!$B$8)*20,1) -> 92 | Q7: =ROUND(P7*O7,1) -> 73.6 | R7: =IF(Q7>=70,"1 - Target now",IF(Q7>=55,"2 - Target next",IF(Q7>=40,"3 - Support only",IF(Q7>=28,"4 - Defer","5 - Do not chase organically")))) -> 1 - Target now | S7: [VERIFIED-SITE] | T7: Hiver already lists CRM web apps as a live service
A8: custom crm software development company | B8: Transactional | C8: US | D8: /services/crm-development/ | E8: Service | F8: DATA REQUIRED | G8: DATA REQUIRED | H8: DATA REQUIRED | I8: [DATA REQUIRED - PAID TOOL] | J8: 5 | K8: 5 | L8: 3 | M8: 4 | N8: B | O8: =IFERROR(INDEX('07 Scoring Model'!$B$14:$B$17,MATCH(N8,'07 Scoring Model'!$A$14:$A$17,0)),0) -> 0.8 | P8: =ROUND((J8*'07 Scoring Model'!$B$5 + K8*'07 Scoring Model'!$B$6 + L8*'07 Scoring Model'!$B$7 + M8*'07 Scoring Model'!$B$8)*20,1) -> 89 | Q8: =ROUND(P8*O8,1) -> 71.2 | R8: =IF(Q8>=70,"1 - Target now",IF(Q8>=55,"2 - Target next",IF(Q8>=40,"3 - Support only",IF(Q8>=28,"4 - Defer","5 - Do not chase organically")))) -> 1 - Target now | S8: [STRATEGIC-JUDGEMENT]
A9: crm integration services | B9: Commercial | C9: UK | D9: /services/crm-development/ | E9: Service | F9: DATA REQUIRED | G9: DATA REQUIRED | H9: DATA REQUIRED | I9: [DATA REQUIRED - PAID TOOL] | J9: 4 | K9: 4 | L9: 3 | M9: 4 | N9: B | O9: =IFERROR(INDEX('07 Scoring Model'!$B$14:$B$17,MATCH(N9,'07 Scoring Model'!$A$14:$A$17,0)),0) -> 0.8 | P9: =ROUND((J9*'07 Scoring Model'!$B$5 + K9*'07 Scoring Model'!$B$6 + L9*'07 Scoring Model'!$B$7 + M9*'07 Scoring Model'!$B$8)*20,1) -> 76 | Q9: =ROUND(P9*O9,1) -> 60.8 | R9: =IF(Q9>=70,"1 - Target now",IF(Q9>=55,"2 - Target next",IF(Q9>=40,"3 - Support only",IF(Q9>=28,"4 - Defer","5 - Do not chase organically")))) -> 2 - Target next | S9: [STRATEGIC-JUDGEMENT]
A10: build a custom crm instead of salesforce | B10: Informational | C10: US | D10: /insights/custom-crm-vs-off-the-shelf/ | E10: Insight | F10: DATA REQUIRED | G10: DATA REQUIRED | H10: DATA REQUIRED | I10: [DATA REQUIRED - PAID TOOL] | J10: 3 | K10: 4 | L10: 2 | M10: 4 | N10: A | O10: =IFERROR(INDEX('07 Scoring Model'!$B$14:$B$17,MATCH(N10,'07 Scoring Model'!$A$14:$A$17,0)),0) -> 1 | P10: =ROUND((J10*'07 Scoring Model'!$B$5 + K10*'07 Scoring Model'!$B$6 + L10*'07 Scoring Model'!$B$7 + M10*'07 Scoring Model'!$B$8)*20,1) -> 65 | Q10: =ROUND(P10*O10,1) -> 65 | R10: =IF(Q10>=70,"1 - Target now",IF(Q10>=55,"2 - Target next",IF(Q10>=40,"3 - Support only",IF(Q10>=28,"4 - Defer","5 - Do not chase organically")))) -> 2 - Target next | S10: [STRATEGIC-JUDGEMENT] | T10: Decision-stage question, low competition
A11: custom crm development cost | B11: Commercial | C11: US | D11: /insights/custom-crm-development-cost/ | E11: Insight | F11: DATA REQUIRED | G11: DATA REQUIRED | H11: DATA REQUIRED | I11: [DATA REQUIRED - PAID TOOL] | J11: 5 | K11: 5 | L11: 3 | M11: 5 | N11: A | O11: =IFERROR(INDEX('07 Scoring Model'!$B$14:$B$17,MATCH(N11,'07 Scoring Model'!$A$14:$A$17,0)),0) -> 1 | P11: =ROUND((J11*'07 Scoring Model'!$B$5 + K11*'07 Scoring Model'!$B$6 + L11*'07 Scoring Model'!$B$7 + M11*'07 Scoring Model'!$B$8)*20,1) -> 92 | Q11: =ROUND(P11*O11,1) -> 92 | R11: =IF(Q11>=70,"1 - Target now",IF(Q11>=55,"2 - Target next",IF(Q11>=40,"3 - Support only",IF(Q11>=28,"4 - Defer","5 - Do not chase organically")))) -> 1 - Target now | S11: [COMPETITOR-DERIVED] | T11: Cost content ranks and pre-qualifies. Needs Hiver's real bands
A12: hire dedicated development team | B12: Transactional | C12: US | D12: /services/dedicated-development-team/ | E12: Service | F12: DATA REQUIRED | G12: DATA REQUIRED | H12: DATA REQUIRED | I12: [DATA REQUIRED - PAID TOOL] | J12: 5 | K12: 5 | L12: 3 | M12: 5 | N12: B | O12: =IFERROR(INDEX('07 Scoring Model'!$B$14:$B$17,MATCH(N12,'07 Scoring Model'!$A$14:$A$17,0)),0) -> 0.8 | P12: =ROUND((J12*'07 Scoring Model'!$B$5 + K12*'07 Scoring Model'!$B$6 + L12*'07 Scoring Model'!$B$7 + M12*'07 Scoring Model'!$B$8)*20,1) -> 92 | Q12: =ROUND(P12*O12,1) -> 73.6 | R12: =IF(Q12>=70,"1 - Target now",IF(Q12>=55,"2 - Target next",IF(Q12>=40,"3 - Support only",IF(Q12>=28,"4 - Defer","5 - Do not chase organically")))) -> 1 - Target now | S12: [STRATEGIC-JUDGEMENT] | T12: The one position where Hiver's structure is an advantage
A13: hire dedicated wordpress developer | B13: Transactional | C13: US | D13: /services/dedicated-development-team/ | E13: Service | F13: DATA REQUIRED | G13: DATA REQUIRED | H13: DATA REQUIRED | I13: [DATA REQUIRED - PAID TOOL] | J13: 5 | K13: 5 | L13: 3 | M13: 5 | N13: A | O13: =IFERROR(INDEX('07 Scoring Model'!$B$14:$B$17,MATCH(N13,'07 Scoring Model'!$A$14:$A$17,0)),0) -> 1 | P13: =ROUND((J13*'07 Scoring Model'!$B$5 + K13*'07 Scoring Model'!$B$6 + L13*'07 Scoring Model'!$B$7 + M13*'07 Scoring Model'!$B$8)*20,1) -> 92 | Q13: =ROUND(P13*O13,1) -> 92 | R13: =IF(Q13>=70,"1 - Target now",IF(Q13>=55,"2 - Target next",IF(Q13>=40,"3 - Support only",IF(Q13>=28,"4 - Defer","5 - Do not chase organically")))) -> 1 - Target now | S13: [STRATEGIC-JUDGEMENT] | T13: Long-tail hire intent, weaker SERP
A14: hire offshore development team | B14: Transactional | C14: UK | D14: /services/dedicated-development-team/ | E14: Service | F14: DATA REQUIRED | G14: DATA REQUIRED | H14: DATA REQUIRED | I14: [DATA REQUIRED - PAID TOOL] | J14: 5 | K14: 4 | L14: 3 | M14: 4 | N14: B | O14: =IFERROR(INDEX('07 Scoring Model'!$B$14:$B$17,MATCH(N14,'07 Scoring Model'!$A$14:$A$17,0)),0) -> 0.8 | P14: =ROUND((J14*'07 Scoring Model'!$B$5 + K14*'07 Scoring Model'!$B$6 + L14*'07 Scoring Model'!$B$7 + M14*'07 Scoring Model'!$B$8)*20,1) -> 83 | Q14: =ROUND(P14*O14,1) -> 66.4 | R14: =IF(Q14>=70,"1 - Target now",IF(Q14>=55,"2 - Target next",IF(Q14>=40,"3 - Support only",IF(Q14>=28,"4 - Defer","5 - Do not chase organically")))) -> 2 - Target next | S14: [STRATEGIC-JUDGEMENT] | T14: Buyer has already accepted the model
A15: dedicated developer monthly cost | B15: Commercial | C15: US | D15: /insights/dedicated-developer-cost/ | E15: Insight | F15: DATA REQUIRED | G15: DATA REQUIRED | H15: DATA REQUIRED | I15: [DATA REQUIRED - PAID TOOL] | J15: 5 | K15: 4 | L15: 2 | M15: 4 | N15: A | O15: =IFERROR(INDEX('07 Scoring Model'!$B$14:$B$17,MATCH(N15,'07 Scoring Model'!$A$14:$A$17,0)),0) -> 1 | P15: =ROUND((J15*'07 Scoring Model'!$B$5 + K15*'07 Scoring Model'!$B$6 + L15*'07 Scoring Model'!$B$7 + M15*'07 Scoring Model'!$B$8)*20,1) -> 79 | Q15: =ROUND(P15*O15,1) -> 79 | R15: =IF(Q15>=70,"1 - Target now",IF(Q15>=55,"2 - Target next",IF(Q15>=40,"3 - Support only",IF(Q15>=28,"4 - Defer","5 - Do not chase organically")))) -> 1 - Target now | S15: [STRATEGIC-JUDGEMENT] | T15: Requires real rate bands from Hiver
A16: offshore vs onshore development agency | B16: Commercial | C16: AU | D16: /insights/offshore-vs-onshore-development/ | E16: Insight | F16: DATA REQUIRED | G16: DATA REQUIRED | H16: DATA REQUIRED | I16: [DATA REQUIRED - PAID TOOL] | J16: 4 | K16: 4 | L16: 2 | M16: 5 | N16: A | O16: =IFERROR(INDEX('07 Scoring Model'!$B$14:$B$17,MATCH(N16,'07 Scoring Model'!$A$14:$A$17,0)),0) -> 1 | P16: =ROUND((J16*'07 Scoring Model'!$B$5 + K16*'07 Scoring Model'!$B$6 + L16*'07 Scoring Model'!$B$7 + M16*'07 Scoring Model'!$B$8)*20,1) -> 75 | Q16: =ROUND(P16*O16,1) -> 75 | R16: =IF(Q16>=70,"1 - Target now",IF(Q16>=55,"2 - Target next",IF(Q16>=40,"3 - Support only",IF(Q16>=28,"4 - Defer","5 - Do not chase organically")))) -> 1 - Target now | S16: [VERIFIED-FILE] | T16: Competitor markets against offshoring; answer it honestly
A17: wordpress development company | B17: Transactional | C17: US | D17: /services/wordpress-development/ | E17: Service | F17: DATA REQUIRED | G17: DATA REQUIRED | H17: DATA REQUIRED | I17: [DATA REQUIRED - PAID TOOL] | J17: 5 | K17: 5 | L17: 4 | M17: 5 | N17: C | O17: =IFERROR(INDEX('07 Scoring Model'!$B$14:$B$17,MATCH(N17,'07 Scoring Model'!$A$14:$A$17,0)),0) -> 0.55 | P17: =ROUND((J17*'07 Scoring Model'!$B$5 + K17*'07 Scoring Model'!$B$6 + L17*'07 Scoring Model'!$B$7 + M17*'07 Scoring Model'!$B$8)*20,1) -> 96 | Q17: =ROUND(P17*O17,1) -> 52.8 | R17: =IF(Q17>=70,"1 - Target now",IF(Q17>=55,"2 - Target next",IF(Q17>=40,"3 - Support only",IF(Q17>=28,"4 - Defer","5 - Do not chase organically")))) -> 3 - Support only | S17: [COMPETITOR-DERIVED] | T17: Head term, heavily contested
A18: wordpress development agency | B18: Transactional | C18: UK | D18: /services/wordpress-development/ | E18: Service | F18: DATA REQUIRED | G18: DATA REQUIRED | H18: DATA REQUIRED | I18: [DATA REQUIRED - PAID TOOL] | J18: 5 | K18: 5 | L18: 3 | M18: 4 | N18: C | O18: =IFERROR(INDEX('07 Scoring Model'!$B$14:$B$17,MATCH(N18,'07 Scoring Model'!$A$14:$A$17,0)),0) -> 0.55 | P18: =ROUND((J18*'07 Scoring Model'!$B$5 + K18*'07 Scoring Model'!$B$6 + L18*'07 Scoring Model'!$B$7 + M18*'07 Scoring Model'!$B$8)*20,1) -> 89 | Q18: =ROUND(P18*O18,1) -> 49 | R18: =IF(Q18>=70,"1 - Target now",IF(Q18>=55,"2 - Target next",IF(Q18>=40,"3 - Support only",IF(Q18>=28,"4 - Defer","5 - Do not chase organically")))) -> 3 - Support only | S18: [STRATEGIC-JUDGEMENT] | T18: Same page; do not split
A19: headless wordpress development | B19: Transactional | C19: US | D19: /services/wordpress-development/headless-wordpress/ | E19: Sub-service | F19: DATA REQUIRED | G19: DATA REQUIRED | H19: DATA REQUIRED | I19: [DATA REQUIRED - PAID TOOL] | J19: 4 | K19: 4 | L19: 2 | M19: 4 | N19: B | O19: =IFERROR(INDEX('07 Scoring Model'!$B$14:$B$17,MATCH(N19,'07 Scoring Model'!$A$14:$A$17,0)),0) -> 0.8 | P19: =ROUND((J19*'07 Scoring Model'!$B$5 + K19*'07 Scoring Model'!$B$6 + L19*'07 Scoring Model'!$B$7 + M19*'07 Scoring Model'!$B$8)*20,1) -> 72 | Q19: =ROUND(P19*O19,1) -> 57.6 | R19: =IF(Q19>=70,"1 - Target now",IF(Q19>=55,"2 - Target next",IF(Q19>=40,"3 - Support only",IF(Q19>=28,"4 - Defer","5 - Do not chase organically")))) -> 2 - Target next | S19: [STRATEGIC-JUDGEMENT] | T19: Technical specificity narrows the field
A20: wordpress maintenance and support plans | B20: Transactional | C20: AU | D20: /services/wordpress-maintenance/ | E20: Service | F20: DATA REQUIRED | G20: DATA REQUIRED | H20: DATA REQUIRED | I20: [DATA REQUIRED - PAID TOOL] | J20: 5 | K20: 4 | L20: 3 | M20: 4 | N20: A | O20: =IFERROR(INDEX('07 Scoring Model'!$B$14:$B$17,MATCH(N20,'07 Scoring Model'!$A$14:$A$17,0)),0) -> 1 | P20: =ROUND((J20*'07 Scoring Model'!$B$5 + K20*'07 Scoring Model'!$B$6 + L20*'07 Scoring Model'!$B$7 + M20*'07 Scoring Model'!$B$8)*20,1) -> 83 | Q20: =ROUND(P20*O20,1) -> 83 | R20: =IF(Q20>=70,"1 - Target now",IF(Q20>=55,"2 - Target next",IF(Q20>=40,"3 - Support only",IF(Q20>=28,"4 - Defer","5 - Do not chase organically")))) -> 1 - Target now | S20: [COMPETITOR-DERIVED] | T20: Retainer revenue; competitor proves the retainer page pattern
A21: elementor to custom theme migration | B21: Transactional | C21: US | D21: /services/wordpress-development/elementor-to-custom-theme/ | E21: Sub-service | F21: DATA REQUIRED | G21: DATA REQUIRED | H21: DATA REQUIRED | I21: [DATA REQUIRED - PAID TOOL] | J21: 4 | K21: 4 | L21: 2 | M21: 4 | N21: A | O21: =IFERROR(INDEX('07 Scoring Model'!$B$14:$B$17,MATCH(N21,'07 Scoring Model'!$A$14:$A$17,0)),0) -> 1 | P21: =ROUND((J21*'07 Scoring Model'!$B$5 + K21*'07 Scoring Model'!$B$6 + L21*'07 Scoring Model'!$B$7 + M21*'07 Scoring Model'!$B$8)*20,1) -> 72 | Q21: =ROUND(P21*O21,1) -> 72 | R21: =IF(Q21>=70,"1 - Target now",IF(Q21>=55,"2 - Target next",IF(Q21>=40,"3 - Support only",IF(Q21>=28,"4 - Defer","5 - Do not chase organically")))) -> 1 - Target now | S21: [VERIFIED-SITE] | T21: Hiver has direct experience of this problem on its own site
A22: wordpress site slow core web vitals fix | B22: Commercial | C22: UK | D22: /services/wordpress-performance-optimisation/ | E22: Service | F22: DATA REQUIRED | G22: DATA REQUIRED | H22: DATA REQUIRED | I22: [DATA REQUIRED - PAID TOOL] | J22: 4 | K22: 4 | L22: 3 | M22: 4 | N22: A | O22: =IFERROR(INDEX('07 Scoring Model'!$B$14:$B$17,MATCH(N22,'07 Scoring Model'!$A$14:$A$17,0)),0) -> 1 | P22: =ROUND((J22*'07 Scoring Model'!$B$5 + K22*'07 Scoring Model'!$B$6 + L22*'07 Scoring Model'!$B$7 + M22*'07 Scoring Model'!$B$8)*20,1) -> 76 | Q22: =ROUND(P22*O22,1) -> 76 | R22: =IF(Q22>=70,"1 - Target now",IF(Q22>=55,"2 - Target next",IF(Q22>=40,"3 - Support only",IF(Q22>=28,"4 - Defer","5 - Do not chase organically")))) -> 1 - Target now | S22: [STRATEGIC-JUDGEMENT] | T22: Problem-led, high intent, weak SERPs
A23: wordpress to webflow or custom which is better | B23: Informational | C23: US | D23: /insights/wordpress-vs-webflow-vs-custom/ | E23: Insight | F23: DATA REQUIRED | G23: DATA REQUIRED | H23: DATA REQUIRED | I23: [DATA REQUIRED - PAID TOOL] | J23: 3 | K23: 3 | L23: 2 | M23: 3 | N23: A | O23: =IFERROR(INDEX('07 Scoring Model'!$B$14:$B$17,MATCH(N23,'07 Scoring Model'!$A$14:$A$17,0)),0) -> 1 | P23: =ROUND((J23*'07 Scoring Model'!$B$5 + K23*'07 Scoring Model'!$B$6 + L23*'07 Scoring Model'!$B$7 + M23*'07 Scoring Model'!$B$8)*20,1) -> 56 | Q23: =ROUND(P23*O23,1) -> 56 | R23: =IF(Q23>=70,"1 - Target now",IF(Q23>=55,"2 - Target next",IF(Q23>=40,"3 - Support only",IF(Q23>=28,"4 - Defer","5 - Do not chase organically")))) -> 2 - Target next | S23: [STRATEGIC-JUDGEMENT]
A24: wordpress website cost | B24: Commercial | C24: AU | D24: /insights/wordpress-website-cost/ | E24: Insight | F24: DATA REQUIRED | G24: DATA REQUIRED | H24: DATA REQUIRED | I24: [DATA REQUIRED - PAID TOOL] | J24: 4 | K24: 4 | L24: 4 | M24: 4 | N24: A | O24: =IFERROR(INDEX('07 Scoring Model'!$B$14:$B$17,MATCH(N24,'07 Scoring Model'!$A$14:$A$17,0)),0) -> 1 | P24: =ROUND((J24*'07 Scoring Model'!$B$5 + K24*'07 Scoring Model'!$B$6 + L24*'07 Scoring Model'!$B$7 + M24*'07 Scoring Model'!$B$8)*20,1) -> 80 | Q24: =ROUND(P24*O24,1) -> 80 | R24: =IF(Q24>=70,"1 - Target now",IF(Q24>=55,"2 - Target next",IF(Q24>=40,"3 - Support only",IF(Q24>=28,"4 - Defer","5 - Do not chase organically")))) -> 1 - Target now | S24: [COMPETITOR-DERIVED]
A25: woocommerce development agency | B25: Transactional | C25: UK | D25: /services/woocommerce-development/ | E25: Service | F25: DATA REQUIRED | G25: DATA REQUIRED | H25: DATA REQUIRED | I25: [DATA REQUIRED - PAID TOOL] | J25: 5 | K25: 4 | L25: 3 | M25: 4 | N25: B | O25: =IFERROR(INDEX('07 Scoring Model'!$B$14:$B$17,MATCH(N25,'07 Scoring Model'!$A$14:$A$17,0)),0) -> 0.8 | P25: =ROUND((J25*'07 Scoring Model'!$B$5 + K25*'07 Scoring Model'!$B$6 + L25*'07 Scoring Model'!$B$7 + M25*'07 Scoring Model'!$B$8)*20,1) -> 83 | Q25: =ROUND(P25*O25,1) -> 66.4 | R25: =IF(Q25>=70,"1 - Target now",IF(Q25>=55,"2 - Target next",IF(Q25>=40,"3 - Support only",IF(Q25>=28,"4 - Defer","5 - Do not chase organically")))) -> 2 - Target next | S25: [STRATEGIC-JUDGEMENT] | T25: Less contested than the Shopify equivalent
A26: woocommerce speed optimisation service | B26: Transactional | C26: UK | D26: /services/woocommerce-development/woocommerce-speed-optimisation/ | E26: Sub-service | F26: DATA REQUIRED | G26: DATA REQUIRED | H26: DATA REQUIRED | I26: [DATA REQUIRED - PAID TOOL] | J26: 5 | K26: 4 | L26: 2 | M26: 4 | N26: A | O26: =IFERROR(INDEX('07 Scoring Model'!$B$14:$B$17,MATCH(N26,'07 Scoring Model'!$A$14:$A$17,0)),0) -> 1 | P26: =ROUND((J26*'07 Scoring Model'!$B$5 + K26*'07 Scoring Model'!$B$6 + L26*'07 Scoring Model'!$B$7 + M26*'07 Scoring Model'!$B$8)*20,1) -> 79 | Q26: =ROUND(P26*O26,1) -> 79 | R26: =IF(Q26>=70,"1 - Target now",IF(Q26>=55,"2 - Target next",IF(Q26>=40,"3 - Support only",IF(Q26>=28,"4 - Defer","5 - Do not chase organically")))) -> 1 - Target now | S26: [STRATEGIC-JUDGEMENT]
A27: woocommerce to shopify migration | B27: Transactional | C27: AU | D27: /services/migrations/woocommerce-to-shopify/ | E27: Migration | F27: DATA REQUIRED | G27: DATA REQUIRED | H27: DATA REQUIRED | I27: [DATA REQUIRED - PAID TOOL] | J27: 5 | K27: 4 | L27: 3 | M27: 4 | N27: B | O27: =IFERROR(INDEX('07 Scoring Model'!$B$14:$B$17,MATCH(N27,'07 Scoring Model'!$A$14:$A$17,0)),0) -> 0.8 | P27: =ROUND((J27*'07 Scoring Model'!$B$5 + K27*'07 Scoring Model'!$B$6 + L27*'07 Scoring Model'!$B$7 + M27*'07 Scoring Model'!$B$8)*20,1) -> 83 | Q27: =ROUND(P27*O27,1) -> 66.4 | R27: =IF(Q27>=70,"1 - Target now",IF(Q27>=55,"2 - Target next",IF(Q27>=40,"3 - Support only",IF(Q27>=28,"4 - Defer","5 - Do not chase organically")))) -> 2 - Target next | S27: [VERIFIED-FILE] | T27: Competitor ranks a dedicated page for this exact pairing
A28: shopify to woocommerce migration | B28: Transactional | C28: US | D28: /services/migrations/shopify-to-woocommerce/ | E28: Migration | F28: DATA REQUIRED | G28: DATA REQUIRED | H28: DATA REQUIRED | I28: [DATA REQUIRED - PAID TOOL] | J28: 5 | K28: 3 | L28: 2 | M28: 3 | N28: A | O28: =IFERROR(INDEX('07 Scoring Model'!$B$14:$B$17,MATCH(N28,'07 Scoring Model'!$A$14:$A$17,0)),0) -> 1 | P28: =ROUND((J28*'07 Scoring Model'!$B$5 + K28*'07 Scoring Model'!$B$6 + L28*'07 Scoring Model'!$B$7 + M28*'07 Scoring Model'!$B$8)*20,1) -> 70 | Q28: =ROUND(P28*O28,1) -> 70 | R28: =IF(Q28>=70,"1 - Target now",IF(Q28>=55,"2 - Target next",IF(Q28>=40,"3 - Support only",IF(Q28>=28,"4 - Defer","5 - Do not chase organically")))) -> 1 - Target now | S28: [STRATEGIC-JUDGEMENT] | T28: Reverse direction is far less served
A29: woocommerce vs shopify for a growing store | B29: Commercial | C29: AU | D29: /insights/woocommerce-vs-shopify/ | E29: Insight | F29: DATA REQUIRED | G29: DATA REQUIRED | H29: DATA REQUIRED | I29: [DATA REQUIRED - PAID TOOL] | J29: 4 | K29: 4 | L29: 4 | M29: 4 | N29: B | O29: =IFERROR(INDEX('07 Scoring Model'!$B$14:$B$17,MATCH(N29,'07 Scoring Model'!$A$14:$A$17,0)),0) -> 0.8 | P29: =ROUND((J29*'07 Scoring Model'!$B$5 + K29*'07 Scoring Model'!$B$6 + L29*'07 Scoring Model'!$B$7 + M29*'07 Scoring Model'!$B$8)*20,1) -> 80 | Q29: =ROUND(P29*O29,1) -> 64 | R29: =IF(Q29>=70,"1 - Target now",IF(Q29>=55,"2 - Target next",IF(Q29>=40,"3 - Support only",IF(Q29>=28,"4 - Defer","5 - Do not chase organically")))) -> 2 - Target next | S29: [VERIFIED-FILE] | T29: Competitor has this; expect a strong incumbent
A30: shopify development agency | B30: Transactional | C30: AU | D30: /services/shopify-ecommerce/ | E30: Service | F30: DATA REQUIRED | G30: DATA REQUIRED | H30: DATA REQUIRED | I30: [DATA REQUIRED - PAID TOOL] | J30: 5 | K30: 5 | L30: 4 | M30: 5 | N30: D | O30: =IFERROR(INDEX('07 Scoring Model'!$B$14:$B$17,MATCH(N30,'07 Scoring Model'!$A$14:$A$17,0)),0) -> 0.25 | P30: =ROUND((J30*'07 Scoring Model'!$B$5 + K30*'07 Scoring Model'!$B$6 + L30*'07 Scoring Model'!$B$7 + M30*'07 Scoring Model'!$B$8)*20,1) -> 96 | Q30: =ROUND(P30*O30,1) -> 24 | R30: =IF(Q30>=70,"1 - Target now",IF(Q30>=55,"2 - Target next",IF(Q30>=40,"3 - Support only",IF(Q30>=28,"4 - Defer","5 - Do not chase organically")))) -> 5 - Do not chase organically | S30: [VERIFIED-FILE] | T30: GATED. Competitor and local agencies own this. Not a first-year target
A31: shopify development company | B31: Transactional | C31: US | D31: /services/shopify-ecommerce/ | E31: Service | F31: DATA REQUIRED | G31: DATA REQUIRED | H31: DATA REQUIRED | I31: [DATA REQUIRED - PAID TOOL] | J31: 5 | K31: 5 | L31: 4 | M31: 5 | N31: D | O31: =IFERROR(INDEX('07 Scoring Model'!$B$14:$B$17,MATCH(N31,'07 Scoring Model'!$A$14:$A$17,0)),0) -> 0.25 | P31: =ROUND((J31*'07 Scoring Model'!$B$5 + K31*'07 Scoring Model'!$B$6 + L31*'07 Scoring Model'!$B$7 + M31*'07 Scoring Model'!$B$8)*20,1) -> 96 | Q31: =ROUND(P31*O31,1) -> 24 | R31: =IF(Q31>=70,"1 - Target now",IF(Q31>=55,"2 - Target next",IF(Q31>=40,"3 - Support only",IF(Q31>=28,"4 - Defer","5 - Do not chase organically")))) -> 5 - Do not chase organically | S31: [STRATEGIC-JUDGEMENT] | T31: GATED. Same page as above
A32: shopify migration services | B32: Transactional | C32: UK | D32: /services/shopify-ecommerce/shopify-migration/ | E32: Sub-service | F32: DATA REQUIRED | G32: DATA REQUIRED | H32: DATA REQUIRED | I32: [DATA REQUIRED - PAID TOOL] | J32: 5 | K32: 4 | L32: 3 | M32: 4 | N32: C | O32: =IFERROR(INDEX('07 Scoring Model'!$B$14:$B$17,MATCH(N32,'07 Scoring Model'!$A$14:$A$17,0)),0) -> 0.55 | P32: =ROUND((J32*'07 Scoring Model'!$B$5 + K32*'07 Scoring Model'!$B$6 + L32*'07 Scoring Model'!$B$7 + M32*'07 Scoring Model'!$B$8)*20,1) -> 83 | Q32: =ROUND(P32*O32,1) -> 45.7 | R32: =IF(Q32>=70,"1 - Target now",IF(Q32>=55,"2 - Target next",IF(Q32>=40,"3 - Support only",IF(Q32>=28,"4 - Defer","5 - Do not chase organically")))) -> 3 - Support only | S32: [VERIFIED-FILE] | T32: GATED
A33: magento to shopify migration | B33: Transactional | C33: UK | D33: /services/migrations/magento-to-shopify/ | E33: Migration | F33: DATA REQUIRED | G33: DATA REQUIRED | H33: DATA REQUIRED | I33: [DATA REQUIRED - PAID TOOL] | J33: 5 | K33: 4 | L33: 3 | M33: 4 | N33: C | O33: =IFERROR(INDEX('07 Scoring Model'!$B$14:$B$17,MATCH(N33,'07 Scoring Model'!$A$14:$A$17,0)),0) -> 0.55 | P33: =ROUND((J33*'07 Scoring Model'!$B$5 + K33*'07 Scoring Model'!$B$6 + L33*'07 Scoring Model'!$B$7 + M33*'07 Scoring Model'!$B$8)*20,1) -> 83 | Q33: =ROUND(P33*O33,1) -> 45.7 | R33: =IF(Q33>=70,"1 - Target now",IF(Q33>=55,"2 - Target next",IF(Q33>=40,"3 - Support only",IF(Q33>=28,"4 - Defer","5 - Do not chase organically")))) -> 3 - Support only | S33: [VERIFIED-FILE] | T33: GATED. Competitor page is ~1,066 words
A34: shopify speed optimisation service | B34: Transactional | C34: US | D34: /services/shopify-ecommerce/shopify-speed-optimisation/ | E34: Sub-service | F34: DATA REQUIRED | G34: DATA REQUIRED | H34: DATA REQUIRED | I34: [DATA REQUIRED - PAID TOOL] | J34: 5 | K34: 4 | L34: 3 | M34: 4 | N34: B | O34: =IFERROR(INDEX('07 Scoring Model'!$B$14:$B$17,MATCH(N34,'07 Scoring Model'!$A$14:$A$17,0)),0) -> 0.8 | P34: =ROUND((J34*'07 Scoring Model'!$B$5 + K34*'07 Scoring Model'!$B$6 + L34*'07 Scoring Model'!$B$7 + M34*'07 Scoring Model'!$B$8)*20,1) -> 83 | Q34: =ROUND(P34*O34,1) -> 66.4 | R34: =IF(Q34>=70,"1 - Target now",IF(Q34>=55,"2 - Target next",IF(Q34>=40,"3 - Support only",IF(Q34>=28,"4 - Defer","5 - Do not chase organically")))) -> 2 - Target next | S34: [VERIFIED-FILE] | T34: GATED. Narrow technical problem, more winnable than the head term
A35: shopify seo services | B35: Transactional | C35: AU | D35: /services/seo/shopify-seo/ | E35: Sub-service | F35: DATA REQUIRED | G35: DATA REQUIRED | H35: DATA REQUIRED | I35: [DATA REQUIRED - PAID TOOL] | J35: 5 | K35: 4 | L35: 3 | M35: 4 | N35: C | O35: =IFERROR(INDEX('07 Scoring Model'!$B$14:$B$17,MATCH(N35,'07 Scoring Model'!$A$14:$A$17,0)),0) -> 0.55 | P35: =ROUND((J35*'07 Scoring Model'!$B$5 + K35*'07 Scoring Model'!$B$6 + L35*'07 Scoring Model'!$B$7 + M35*'07 Scoring Model'!$B$8)*20,1) -> 83 | Q35: =ROUND(P35*O35,1) -> 45.7 | R35: =IF(Q35>=70,"1 - Target now",IF(Q35>=55,"2 - Target next",IF(Q35>=40,"3 - Support only",IF(Q35>=28,"4 - Defer","5 - Do not chase organically")))) -> 3 - Support only | S35: [VERIFIED-FILE] | T35: GATED
A36: hire shopify developer | B36: Transactional | C36: US | D36: /services/dedicated-development-team/ | E36: Service | F36: DATA REQUIRED | G36: DATA REQUIRED | H36: DATA REQUIRED | I36: [DATA REQUIRED - PAID TOOL] | J36: 5 | K36: 4 | L36: 4 | M36: 4 | N36: C | O36: =IFERROR(INDEX('07 Scoring Model'!$B$14:$B$17,MATCH(N36,'07 Scoring Model'!$A$14:$A$17,0)),0) -> 0.55 | P36: =ROUND((J36*'07 Scoring Model'!$B$5 + K36*'07 Scoring Model'!$B$6 + L36*'07 Scoring Model'!$B$7 + M36*'07 Scoring Model'!$B$8)*20,1) -> 87 | Q36: =ROUND(P36*O36,1) -> 47.9 | R36: =IF(Q36>=70,"1 - Target now",IF(Q36>=55,"2 - Target next",IF(Q36>=40,"3 - Support only",IF(Q36>=28,"4 - Defer","5 - Do not chase organically")))) -> 3 - Support only | S36: [STRATEGIC-JUDGEMENT] | T36: GATED. Route to the dedicated-team page, not a new one
A37: shopify development cost | B37: Commercial | C37: US | D37: /insights/shopify-development-cost/ | E37: Insight | F37: DATA REQUIRED | G37: DATA REQUIRED | H37: DATA REQUIRED | I37: [DATA REQUIRED - PAID TOOL] | J37: 4 | K37: 4 | L37: 4 | M37: 4 | N37: B | O37: =IFERROR(INDEX('07 Scoring Model'!$B$14:$B$17,MATCH(N37,'07 Scoring Model'!$A$14:$A$17,0)),0) -> 0.8 | P37: =ROUND((J37*'07 Scoring Model'!$B$5 + K37*'07 Scoring Model'!$B$6 + L37*'07 Scoring Model'!$B$7 + M37*'07 Scoring Model'!$B$8)*20,1) -> 80 | Q37: =ROUND(P37*O37,1) -> 64 | R37: =IF(Q37>=70,"1 - Target now",IF(Q37>=55,"2 - Target next",IF(Q37>=40,"3 - Support only",IF(Q37>=28,"4 - Defer","5 - Do not chase organically")))) -> 2 - Target next | S37: [VERIFIED-FILE] | T37: GATED
A38: shopify xero integration | B38: Transactional | C38: AU | D38: /services/integrations/shopify-xero/ | E38: Integration | F38: DATA REQUIRED | G38: DATA REQUIRED | H38: DATA REQUIRED | I38: [DATA REQUIRED - PAID TOOL] | J38: 5 | K38: 4 | L38: 2 | M38: 4 | N38: B | O38: =IFERROR(INDEX('07 Scoring Model'!$B$14:$B$17,MATCH(N38,'07 Scoring Model'!$A$14:$A$17,0)),0) -> 0.8 | P38: =ROUND((J38*'07 Scoring Model'!$B$5 + K38*'07 Scoring Model'!$B$6 + L38*'07 Scoring Model'!$B$7 + M38*'07 Scoring Model'!$B$8)*20,1) -> 79 | Q38: =ROUND(P38*O38,1) -> 63.2 | R38: =IF(Q38>=70,"1 - Target now",IF(Q38>=55,"2 - Target next",IF(Q38>=40,"3 - Support only",IF(Q38>=28,"4 - Defer","5 - Do not chase organically")))) -> 2 - Target next | S38: [VERIFIED-FILE] | T38: GATED. Competitor page ~985 words
A39: wordpress hubspot integration | B39: Transactional | C39: US | D39: /services/integrations/wordpress-hubspot/ | E39: Integration | F39: DATA REQUIRED | G39: DATA REQUIRED | H39: DATA REQUIRED | I39: [DATA REQUIRED - PAID TOOL] | J39: 5 | K39: 4 | L39: 2 | M39: 4 | N39: A | O39: =IFERROR(INDEX('07 Scoring Model'!$B$14:$B$17,MATCH(N39,'07 Scoring Model'!$A$14:$A$17,0)),0) -> 1 | P39: =ROUND((J39*'07 Scoring Model'!$B$5 + K39*'07 Scoring Model'!$B$6 + L39*'07 Scoring Model'!$B$7 + M39*'07 Scoring Model'!$B$8)*20,1) -> 79 | Q39: =ROUND(P39*O39,1) -> 79 | R39: =IF(Q39>=70,"1 - Target now",IF(Q39>=55,"2 - Target next",IF(Q39>=40,"3 - Support only",IF(Q39>=28,"4 - Defer","5 - Do not chase organically")))) -> 1 - Target now | S39: [COMPETITOR-DERIVED] | T39: Pattern transferred to Hiver's real stack
A40: wordpress salesforce integration | B40: Transactional | C40: US | D40: /services/integrations/wordpress-salesforce/ | E40: Integration | F40: DATA REQUIRED | G40: DATA REQUIRED | H40: DATA REQUIRED | I40: [DATA REQUIRED - PAID TOOL] | J40: 5 | K40: 4 | L40: 2 | M40: 4 | N40: A | O40: =IFERROR(INDEX('07 Scoring Model'!$B$14:$B$17,MATCH(N40,'07 Scoring Model'!$A$14:$A$17,0)),0) -> 1 | P40: =ROUND((J40*'07 Scoring Model'!$B$5 + K40*'07 Scoring Model'!$B$6 + L40*'07 Scoring Model'!$B$7 + M40*'07 Scoring Model'!$B$8)*20,1) -> 79 | Q40: =ROUND(P40*O40,1) -> 79 | R40: =IF(Q40>=70,"1 - Target now",IF(Q40>=55,"2 - Target next",IF(Q40>=40,"3 - Support only",IF(Q40>=28,"4 - Defer","5 - Do not chase organically")))) -> 1 - Target now | S40: [COMPETITOR-DERIVED]
...

Sheet 09 URL Map
A1: Site architecture and URL map
A2: Capability column gates publication. GATED and DATA REQUIRED rows must not go live until Hiver confirms the capability.
A3: URL | B3: Parent | C3: Page type | D3: Priority | E3: Primary keyword | F3: Intent | G3: Country | H3: Tier | I3: Capability | J3: Build status | K3: Note
A4: / | B4: - | C4: Home | D4: P0 | E4: hiver technology | F4: Navigational | G4: Global | H4: A | I4: Confirmed | J4: Rebuild | K4: Rewrite title and H1 around what Hiver actually does and for whom
A5: /services/ | B5: / | C5: Hub | D5: P0 | E5: software development services | F5: Commercial | G5: Global | H5: C | I5: Confirmed | J5: Build | K5: Real hub with 150+ words of orientation per child, not a link grid
A6: /services/web-application-development/ | B6: /services/ | C6: Service | D6: P0 | E6: custom web application development | F6: Transactional | G6: US | H6: C | I6: Confirmed | J6: Build | K6: Flagship page. Target 1,400-1,600 words per the competitor depth benchmark
A7: /services/crm-development/ | B7: /services/ | C7: Service | D7: P0 | E7: custom crm development | F7: Transactional | G7: US | H7: B | I7: Confirmed | J7: Build | K7: Already a live listed service; highest deal value of the confirmed set
A8: /services/wordpress-development/ | B8: /services/ | C8: Service | D8: P0 | E8: wordpress development company | F8: Transactional | G8: US | H8: C | I8: Confirmed | J8: Build
A9: /services/wordpress-development/headless-wordpress/ | B9: /services/wordpress-development/ | C9: Sub-service | D9: P2 | E9: headless wordpress development | F9: Transactional | G9: US | H9: B | I9: DATA REQUIRED | J9: Build | K9: Only if Hiver has shipped a headless build
A10: /services/wordpress-development/elementor-to-custom-theme/ | B10: /services/wordpress-development/ | C10: Sub-service | D10: P1 | E10: elementor to custom theme migration | F10: Transactional | G10: US | H10: A | I10: Confirmed | J10: Build | K10: Hiver can write this from its own migration experience
A11: /services/wordpress-maintenance/ | B11: /services/ | C11: Service | D11: P1 | E11: wordpress maintenance and support plans | F11: Transactional | G11: AU | H11: A | I11: Confirmed | J11: Build | K11: Retainer revenue; needs real plan tiers and pricing
A12: /services/wordpress-performance-optimisation/ | B12: /services/ | C12: Service | D12: P1 | E12: wordpress core web vitals fix | F12: Commercial | G12: UK | H12: A | I12: Confirmed | J12: Build | K12: Problem-led page; requires before/after evidence
A13: /services/mobile-app-development/ | B13: /services/ | C13: Service | D13: P0 | E13: mobile app development company | F13: Transactional | G13: US | H13: D | I13: Confirmed | J13: Build | K13: Needed for completeness; do not expect it to rank on the head term
A14: /services/ui-ux-design/ | B14: /services/ | C14: Service | D14: P1 | E14: ui ux design agency for saas | F14: Transactional | G14: US | H14: C | I14: Confirmed | J14: Build | K14: Merge the Figma offering into this page
A15: /services/dedicated-development-team/ | B15: /services/ | C15: Service | D15: P0 | E15: hire dedicated development team | F15: Transactional | G15: US | H15: B | I15: Confirmed | J15: Build | K15: The one page where Hiver's structure is an advantage. Handle the offshore objection head-on
A16: /services/woocommerce-development/ | B16: /services/ | C16: Service | D16: P1 | E16: woocommerce development agency | F16: Transactional | G16: UK | H16: B | I16: DATA REQUIRED | J16: Build | K16: Less contested than Shopify and closer to Hiver's WordPress base
A17: /services/woocommerce-development/woocommerce-speed-optimisation/ | B17: /services/woocommerce-development/ | C17: Sub-service | D17: P2 | E17: woocommerce speed optimisation service | F17: Transactional | G17: UK | H17: A | I17: DATA REQUIRED | J17: Build
A18: /services/shopify-ecommerce/ | B18: /services/ | C18: Service | D18: P1 | E18: shopify development agency | F18: Transactional | G18: AU | H18: D | I18: GATED | J18: Blocked | K18: Do not publish until Hiver confirms delivered Shopify stores and Partner status
A19: /services/shopify-ecommerce/shopify-store-development/ | B19: /services/shopify-ecommerce/ | C19: Sub-service | D19: P2 | E19: shopify store development | F19: Transactional | G19: US | H19: C | I19: GATED | J19: Blocked
A20: /services/shopify-ecommerce/shopify-migration/ | B20: /services/shopify-ecommerce/ | C20: Sub-service | D20: P2 | E20: shopify migration services | F20: Transactional | G20: UK | H20: C | I20: GATED | J20: Blocked
A21: /services/shopify-ecommerce/shopify-speed-optimisation/ | B21: /services/shopify-ecommerce/ | C21: Sub-service | D21: P2 | E21: shopify speed optimisation service | F21: Transactional | G21: US | H21: B | I21: GATED | J21: Blocked | K21: Most winnable of the Shopify set because the problem is narrow
A22: /services/seo/ | B22: /services/ | C22: Hub | D22: P1 | E22: seo services | F22: Commercial | G22: Global | H22: D | I22: DATA REQUIRED | J22: Build | K22: Hiver must be able to point at its own ranking site before selling SEO
A23: /services/seo/technical-seo/ | B23: /services/seo/ | C23: Sub-service | D23: P1 | E23: technical seo agency | F23: Transactional | G23: UK | H23: C | I23: DATA REQUIRED | J23: Build
A24: /services/seo/ecommerce-seo/ | B24: /services/seo/ | C24: Sub-service | D24: P2 | E24: ecommerce seo agency | F24: Transactional | G24: US | H24: C | I24: DATA REQUIRED | J24: Build
A25: /services/seo/wordpress-seo/ | B25: /services/seo/ | C25: Sub-service | D25: P2 | E25: wordpress seo services | F25: Transactional | G25: UK | H25: B | I25: DATA REQUIRED | J25: Build
A26: /services/seo/seo-audit/ | B26: /services/seo/ | C26: Sub-service | D26: P1 | E26: seo audit service | F26: Transactional | G26: AU | H26: B | I26: DATA REQUIRED | J26: Build | K26: Doubles as the primary lead magnet
A27: /services/seo/shopify-seo/ | B27: /services/seo/ | C27: Sub-service | D27: P3 | E27: shopify seo services | F27: Transactional | G27: AU | H27: C | I27: GATED | J27: Blocked
A28: /services/digital-marketing/ | B28: /services/ | C28: Hub | D28: P1 | E28: digital marketing agency | F28: Transactional | G28: US | H28: D | I28: Confirmed | J28: Build
A29: /services/digital-marketing/google-ads/ | B29: /services/digital-marketing/ | C29: Sub-service | D29: P2 | E29: google ads management for ecommerce | F29: Transactional | G29: AU | H29: C | I29: DATA REQUIRED | J29: Build
A30: /services/digital-marketing/meta-ads/ | B30: /services/digital-marketing/ | C30: Sub-service | D30: P2 | E30: meta ads agency | F30: Transactional | G30: US | H30: C | I30: Confirmed | J30: Build
A31: /services/marketing-automation/ | B31: /services/ | C31: Service | D31: P1 | E31: lifecycle email marketing services | F31: Transactional | G31: UK | H31: B | I31: Confirmed | J31: Build | K31: CONSOLIDATION: absorbs email marketing, newsletters, welcome sequences, win-back, cart recovery, lead nurture and CRM follow-up. Seven briefed pages become one
A32: /services/marketing-automation/klaviyo/ | B32: /services/marketing-automation/ | C32: Sub-service | D32: P3 | E32: klaviyo email marketing agency | F32: Transactional | G32: AU | H32: C | I32: GATED | J32: Blocked
A33: /services/integrations/ | B33: /services/ | C33: Hub | D33: P1 | E33: custom api integration development | F33: Transactional | G33: US | H33: B | I33: Confirmed | J33: Build | K33: Hub for the highest-yield long-tail pattern in the competitor dataset
A34: /services/integrations/wordpress-hubspot/ | B34: /services/integrations/ | C34: Integration | D34: P2 | E34: wordpress hubspot integration | F34: Transactional | G34: US | H34: A | I34: DATA REQUIRED | J34: Build | K34: Target ~950 words, 8-9 H2s, following the observed integration template
